Workbook
Name NU_Codes: 'Northeastern Courses'!$A$2:$A$39
Name NYU_Codes: 'NYU Courses'!$A$2:$A$39

Sheet README
A1: Transfer Program & Course Match Workbook
A2: Purpose | B2: Preliminary program and course matching for transfer students moving between Boston University (BU) and two comparable US universities. Built for a hackathon prototype.
A3: Peer universities | B3: Northeastern University (Boston; private research university; same city and similar size) and New York University (private urban research university; similar 4-credit, arts & sciences course structure).
A4: Scope | B4: Five common transfer majors: Computer Science, Economics, Psychology, Biology (with supporting chemistry) and Mathematics. Core and commonly required courses only, not full catalogs.
A5: Important | B5: Matches are a starting point, not official equivalencies. At BU, final decisions are made by the Credit Evaluation Department and academic department evaluators, often after a syllabus review.
A6: Sheets
A7: Programs | B7: Program-level match across the three universities, with key transfer rules.
A8: BU Courses / Northeastern Courses / NYU Courses | B8: Course catalogs for each university (code, title, program, requirement type, credits, verification status, source).
A9: Course Match | B9: Each BU course mapped to its closest Northeastern and NYU course, with a match level. Titles and credits are pulled by formula from the course sheets.
A10: Match Summary | B10: Counts of match levels by program and university (formulas).
A11: Transfer Lookup | B11: Pick a school and a course code; the sheet returns the likely BU equivalent.
A12: Match levels
A13: Likely equivalent | B13: Content and level line up closely.
A14: Partial - syllabus review | B14: Overlapping content; a syllabus review is needed, or the course may map to a different or combined BU course.
A15: No equivalent found | B15: No comparable course found in the peer's core requirements (an elective may still exist).
A16: Must be taken at BU | B16: BU requires this course in residence, so transfer credit will not satisfy it.
A17: Verified column | B17: Yes = code and title confirmed against the university's published catalog or bulletin. Check = code confirmed but title or credits from memory; confirm before relying on it.
A18: Credits | B18: All three use semester credit hours. Northeastern often bundles a 1-credit lab with a 4-credit course (shown as 5).
A19: Source date | B19: Catalogs and bulletins consulted October 2026 (Northeastern 2026–2027 catalog; current BU Bulletin and NYU Bulletins). Requirements change; re-check each source link.

Sheet Transfer Lookup
A1: Transfer Course Lookup
A2: Fill in the two yellow cells. Results update automatically.
A4: Coming from | B4: Northeastern
A5: Course code | B5: CS 3000
A7: Result
A8: Course title | B8: =IFERROR(IF($B$4="NYU",INDEX('NYU Courses'!$B$2:$B$39,MATCH($B$5,NYU_Codes,0)),INDEX('Northeastern Courses'!$B$2:$B$39,MATCH($B$5,NU_Codes,0))),"Code not found") -> Algorithms and Data
A9: Likely BU equivalent | B9: =IFERROR(IF($B$4="NYU",INDEX('Course Match'!$A$2:$A$42,MATCH($B$5,'Course Match'!$I$2:$I$42,0)),INDEX('Course Match'!$A$2:$A$42,MATCH($B$5,'Course Match'!$E$2:$E$42,0))),"No BU match on file - send syllabus for review") -> CAS CS 330
A10: BU course title | B10: =IFERROR(INDEX('BU Courses'!$B$2:$B$42,MATCH(B9,'BU Courses'!$A$2:$A$42,0)),"—") -> Introduction to the Analysis of Algorithms
A11: Match level | B11: =IFERROR(IF($B$4="NYU",INDEX('Course Match'!$L$2:$L$42,MATCH($B$5,'Course Match'!$I$2:$I$42,0)),INDEX('Course Match'!$H$2:$H$42,MATCH($B$5,'Course Match'!$E$2:$E$42,0))),"—") -> Likely equivalent
A12: Notes | B12: =IFERROR(IF($B$4="NYU",INDEX('Course Match'!$M$2:$M$42,MATCH($B$5,'Course Match'!$I$2:$I$42,0)),INDEX('Course Match'!$M$2:$M$42,MATCH($B$5,'Course Match'!$E$2:$E$42,0))),"No BU match on file - send syllabus for review") -> Algorithms.
A14: Where a peer course maps to more than one BU course (e.g. Northeastern CHEM 1161), the first match is shown; see the Notes and the Course Match sheet.

Sheet Programs
A1: Program area | B1: BU program | C1: BU school | D1: BU degree | E1: BU key rules | F1: BU source | G1: Northeastern program | H1: NU college | I1: NU degree | J1: NU key requirements | K1: NU source | L1: NYU program | M1: NYU school | N1: NYU degree | O1: NYU key requirements | P1: NYU source | Q1: Program match | R1: Notes
A2: Computer Science | B2: BA in Computer Science | C2: College of Arts & Sciences | D2: BA | E2: 15 courses; Group C (CS 320, 332, 350) cannot be transferred | F2: https://www.bu.edu/academics/cas/programs/computer-science/ba/ | G2: Computer Science, BSCS (Boston) | H2: Khoury College of Computer Sciences | I2: BS | J2: 72 SH in major; co-op based; BACS also offered | K2: https://catalog.northeastern.edu/undergraduate/computer-information-science/computer-science/bscs/ | L2: Computer Science (BA) | M2: College of Arts & Science | N2: BA | O2: 12 courses | P2: https://bulletins.nyu.edu/undergraduate/arts-science/programs/computer-science-ba/computer-science-ba.pdf | Q2: Strong | R2: NU uses 4–5 SH courses with labs and a new CS 2000/2100/3100 intro sequence.
A3: Economics | B3: BA in Economics | C3: College of Arts & Sciences | D3: BA | E3: 12 courses; max 4 courses at 200+ level transferred after matriculation | F3: https://www.bu.edu/academics/cas/programs/economics/ba | G3: Economics, BS (combined majors shown) | H3: College of Social Sciences and Humanities | I3: BS | J3: Core: ECON 1115, 1116, 2315, 2316, 2350, 2560 | K3: https://catalog.northeastern.edu/undergraduate/social-sciences-humanities/economics/economics-mathematics-bs/ | L3: Economics (BA) | M3: College of Arts & Science | N3: BA | O3: Policy and Theory concentrations | P3: https://bulletins.nyu.edu/undergraduate/arts-science/programs/economics-ba/economics-ba.pdf | Q3: Strong | R3: All three share principles, intermediate theory, statistics and econometrics.
A4: Psychology | B4: BA in Psychology | C4: College of Arts & Sciences | D4: BA | E4: PS 101 + 9 principal courses; PS 231 required | F4: https://www.bu.edu/academics/cas/programs/psychology/ba/ | G4: Psychology, BS | H4: College of Science | I4: BS | J4: PSYC 1101, PSYC 2320 and core content courses | K4: https://catalog.northeastern.edu/undergraduate/science/psychology/psychology-bs | L4: Psychology (BA) | M4: College of Arts & Science | N4: BA | O4: Intro, statistics and core content courses | P4: https://bulletins.nyu.edu/courses/psych_ua/psych_ua.pdf | Q4: Moderate | R4: Statistics and experimental design are organized differently at each school.
A5: Biology | B5: BA in Biology | C5: College of Arts & Sciences | D5: BA | E5: At least 5 BI courses beyond BI 107/108 must be taken at BU | F5: https://www.bu.edu/academics/cas/departments/biology/ | G5: Biology, BS | H5: College of Science | I5: BS | J5: BIOL 1107, 2299, 2301, 2309, 3611 + chemistry | K5: https://catalog.northeastern.edu/undergraduate/science/biology/biology-bs/ | L5: Biology major (standard track) | M5: College of Arts & Science | N5: See bulletin | O5: BIOL-UA 11, 12, 21, 22 required | P5: https://courses.bio.nyu.edu/requirement/major-standard-track/required | Q5: Moderate | R5: NU teaches general chemistry as one accelerated course.
A6: Mathematics | B6: BA in Mathematics | C6: College of Arts & Sciences | D6: BA | E6: Calculus sequence MA 123/124/225 plus MA 242 | F6: https://www.bu.edu/math/undergraduate/faqs-and-forms/ | G6: Mathematics (see combined majors) | H6: College of Science | I6: BS | J6: MATH 1341, 1342, 2321, 2341, 3081 | K6: https://catalog.northeastern.edu/undergraduate/science/biology/biology-mathematics-bs | L6: Mathematics | M6: College of Arts & Science | N6: BA | O6: MATH-UA 121, 122, 123, 140 | P6: https://math.nyu.edu/media/math/filer_public/f8/eb/f8eb4d2e-81c8-4421-8f62-fc2683e63e64/csma_major_honors_check_sheet.pdf | Q6: Strong | R6: Calculus and linear algebra sequences align closely.

Sheet BU Courses
A1: Course code | B1: Course title | C1: Program | D1: Requirement type | E1: Credits | F1: Verified | G1: Notes | H1: Source
A2: CAS CS 111 | B2: Introduction to Computer Science 1 | C2: Computer Science | D2: Core (Group A) | E2: 4 | F2: Yes | H2: https://www.bu.edu/academics/cas/programs/computer-science/ba/
A3: CAS CS 112 | B3: Introduction to Computer Science 2 | C3: Computer Science | D3: Core (Group A) | E3: 4 | F3: Yes | H3: https://www.bu.edu/academics/cas/programs/computer-science/ba/
A4: CAS CS 131 | B4: Combinatoric Structures | C4: Computer Science | D4: Core (Group A) | E4: 4 | F4: Yes | H4: https://www.bu.edu/academics/cas/programs/computer-science/ba/
A5: CAS CS 210 | B5: Computer Systems | C5: Computer Science | D5: Core (Group A) | E5: 4 | F5: Yes | H5: https://www.bu.edu/academics/cas/programs/computer-science/ba/
A6: CAS CS 330 | B6: Introduction to the Analysis of Algorithms | C6: Computer Science | D6: Core (Group A) | E6: 4 | F6: Yes | H6: https://www.bu.edu/academics/cas/programs/computer-science/ba/
A7: CAS CS 132 | B7: Geometric Algorithms | C7: Computer Science | D7: Group B (choose) | E7: 4 | F7: Yes | G7: CAS MA 242 may substitute | H7: https://www.bu.edu/academics/cas/programs/computer-science/ba/
A8: CAS CS 235 | B8: Algebraic Algorithms | C8: Computer Science | D8: Group B (choose) | E8: 4 | F8: Yes | G8: CAS MA 294 may substitute | H8: https://www.bu.edu/academics/cas/programs/computer-science/ba/
A9: CAS CS 237 | B9: Probability in Computing | C9: Computer Science | D9: Group B (choose) | E9: 4 | F9: Yes | G9: CAS MA 581 may substitute | H9: https://www.bu.edu/academics/cas/programs/computer-science/ba/
A10: CAS CS 320 | B10: Concepts of Programming Languages | C10: Computer Science | D10: Group C (BU only) | E10: 4 | F10: Yes | G10: Must be taken at BU; cannot be transferred | H10: https://www.bu.edu/academics/cas/programs/computer-science/ba/
A11: CAS CS 332 | B11: Elements of the Theory of Computation | C11: Computer Science | D11: Group C (BU only) | E11: 4 | F11: Yes | G11: Must be taken at BU; cannot be transferred | H11: https://www.bu.edu/academics/cas/programs/computer-science/ba/
A12: CAS CS 350 | B12: Fundamentals of Computing Systems | C12: Computer Science | D12: Group C (BU only) | E12: 4 | F12: Yes | G12: Must be taken at BU; cannot be transferred | H12: https://www.bu.edu/academics/cas/programs/computer-science/ba/
A13: CAS EC 101 | B13: Introductory Microeconomic Analysis | C13: Economics | D13: Intro | E13: 4 | F13: Yes | H13: https://www.bu.edu/academics/cas/programs/economics/ba
A14: CAS EC 102 | B14: Introductory Macroeconomic Analysis | C14: Economics | D14: Intro | E14: 4 | F14: Yes | H14: https://www.bu.edu/academics/cas/programs/economics/ba
A15: CAS EC 201 | B15: Intermediate Microeconomic Analysis | C15: Economics | D15: Core | E15: 4 | F15: Yes | G15: Max 4 courses at 200+ level transferable after matriculation | H15: https://www.bu.edu/academics/cas/programs/economics/ba
A16: CAS EC 202 | B16: Intermediate Macroeconomic Analysis | C16: Economics | D16: Core | E16: 4 | F16: Yes | G16: Max 4 courses at 200+ level transferable after matriculation | H16: https://www.bu.edu/academics/cas/programs/economics/ba
A17: CAS EC 203 | B17: Empirical Economics 1 | C17: Economics | D17: Core | E17: 4 | F17: Yes | G17: MA 115, MA 213 or QST QM 221 accepted as substitutes | H17: https://www.bu.edu/academics/cas/programs/economics/ba
A18: CAS EC 204 | B18: Empirical Economics 2 | C18: Economics | D18: Core | E18: 4 | F18: Yes | H18: https://www.bu.edu/academics/cas/programs/economics/ba
A19: CAS PS 101 | B19: General Psychology | C19: Psychology | D19: Prerequisite | E19: 4 | F19: Yes | H19: https://www.bu.edu/academics/cas/programs/psychology/ba/
A20: CAS PS 211 | B20: Experimental Design in Psychology | C20: Psychology | D20: Design & Statistics | E20: 4 | F20: Yes | G20: Or MA 115 + MA 116; not a principal course | H20: https://www.bu.edu/academics/cas/programs/psychology/ba/
A21: CAS PS 231 | B21: Physiological Psychology | C21: Psychology | D21: Required principal | E21: 4 | F21: Yes | H21: https://www.bu.edu/academics/cas/programs/psychology/ba/
A22: CAS PS 222 | B22: Perception and Behavior | C22: Psychology | D22: Group A | E22: 4 | F22: Yes | H22: https://www.bu.edu/academics/cas/programs/psychology/ba/
A23: CAS PS 336 | B23: Introduction to Cognitive Psychology | C23: Psychology | D23: Group A | E23: 4 | F23: Yes | H23: https://www.bu.edu/academics/cas/programs/psychology/ba/
A24: CAS PS 241 | B24: Developmental Psychology | C24: Psychology | D24: Group B | E24: 4 | F24: Yes | H24: https://www.bu.edu/academics/cas/programs/psychology/ba/
A25: CAS PS 251 | B25: Psychology of Personality: Theories and Application | C25: Psychology | D25: Group B | E25: 4 | F25: Yes | H25: https://www.bu.edu/academics/cas/programs/psychology/ba/
A26: CAS PS 261 | B26: Social Psychology | C26: Psychology | D26: Group B | E26: 4 | F26: Yes | H26: https://www.bu.edu/academics/cas/programs/psychology/ba/
A27: CAS PS 371 | B27: Psychopathology | C27: Psychology | D27: Group B | E27: 4 | F27: Yes | G27: Formerly Abnormal Psychology | H27: https://www.bu.edu/academics/cas/programs/psychology/ba/
A28: CAS BI 107 | B28: Biology 1 | C28: Biology | D28: Intro | E28: 4 | F28: Yes | H28: https://www.bu.edu/academics/cas/departments/biology/
A29: CAS BI 108 | B29: Biology 2 | C29: Biology | D29: Intro | E29: 4 | F29: Yes | H29: https://www.bu.edu/academics/cas/departments/biology/
A30: CAS BI 203 | B30: Cell Biology | C30: Biology | D30: Core | E30: 4 | F30: Yes | H30: https://www.bu.edu/scied/academics/specialization-in-biology/
A31: CAS BI 206 | B31: Genetics | C31: Biology | D31: Core | E31: 4 | F31: Yes | H31: https://www.bu.edu/scied/academics/specialization-in-biology/
A32: CAS CH 101 | B32: General Chemistry 1 | C32: Biology | D32: Supporting (Chemistry) | E32: 4 | F32: Yes | H32: https://www.bu.edu/scied/academics/specialization-in-biology/
A33: CAS CH 102 | B33: General Chemistry 2 | C33: Biology | D33: Supporting (Chemistry) | E33: 4 | F33: Yes | H33: https://www.bu.edu/scied/academics/specialization-in-biology/
A34: CAS CH 203 | B34: Organic Chemistry 1 | C34: Biology | D34: Supporting (Chemistry) | E34: 4 | F34: Yes | H34: https://www.bu.edu/scied/academics/specialization-in-biology/
A35: CAS CH 204 | B35: Organic Chemistry 2 | C35: Biology | D35: Supporting (Chemistry) | E35: 4 | F35: Yes | H35: https://www.bu.edu/scied/academics/specialization-in-biology/
A36: CAS MA 123 | B36: Calculus I | C36: Mathematics | D36: Lower division | E36: 4 | F36: Yes | H36: https://www.bu.edu/math/undergraduate/faqs-and-forms/
A37: CAS MA 124 | B37: Calculus II | C37: Mathematics | D37: Lower division | E37: 4 | F37: Yes | H37: https://www.bu.edu/math/undergraduate/faqs-and-forms/
A38: CAS MA 225 | B38: Multivariate Calculus | C38: Mathematics | D38: Lower division | E38: 4 | F38: Yes | H38: https://www.bu.edu/math/undergraduate/faqs-and-forms/
A39: CAS MA 242 | B39: Linear Algebra | C39: Mathematics | D39: Lower division | E39: 4 | F39: Yes | H39: https://bu.edu/academics/cas/programs/mathematics-statistics/ba-mathematics-computer-science
A40: CAS MA 226 | B40: Differential Equations | C40: Mathematics | D40: Lower division | E40: 4 | F40: Check | G40: Title from memory; confirm in Bulletin | H40: https://www.bu.edu/math/undergraduate/faqs-and-forms/
...

Sheet Northeastern Courses
A1: Course code | B1: Course title | C1: Program | D1: Requirement type | E1: Credits | F1: Verified | G1: Notes | H1: Source
A2: CS 2000 | B2: Introduction to Program Design and Implementation | C2: Computer Science | D2: Fundamental | E2: 5 | F2: Yes | G2: Includes CS 2001 lab | H2: https://catalog.northeastern.edu/undergraduate/computer-information-science/computer-science/bscs/
A3: CS 2100 | B3: Program Design and Implementation 1 | C3: Computer Science | D3: Fundamental | E3: 5 | F3: Yes | G3: Includes CS 2101 lab | H3: https://catalog.northeastern.edu/undergraduate/computer-information-science/computer-science/bscs/
A4: CS 3100 | B4: Program Design and Implementation 2 | C4: Computer Science | D4: Required | E4: 5 | F4: Yes | G4: Includes CS 3101 lab | H4: https://catalog.northeastern.edu/undergraduate/computer-information-science/computer-science/bscs/
A5: CS 1800 | B5: Discrete Structures | C5: Computer Science | D5: Fundamental | E5: 4 | F5: Yes | H5: https://catalog.northeastern.edu/undergraduate/computer-information-science/computer-science/bscs/
A6: CS 2700 | B6: Data Structures and Analysis | C6: Computer Science | D6: Required | E6: 5 | F6: Yes | G6: Includes CS 2701 lab | H6: https://catalog.northeastern.edu/undergraduate/computer-information-science/computer-science/bscs/
A7: CS 3000 | B7: Algorithms and Data | C7: Computer Science | D7: Required | E7: 4 | F7: Yes | H7: https://catalog.northeastern.edu/undergraduate/computer-information-science/computer-science/bscs/
A8: CS 3650 | B8: Computer Systems | C8: Computer Science | D8: Required | E8: 4 | F8: Yes | H8: https://catalog.northeastern.edu/undergraduate/computer-information-science/computer-science/bscs/
A9: CS 3800 | B9: Theory of Computation | C9: Computer Science | D9: Required | E9: 4 | F9: Yes | H9: https://catalog.northeastern.edu/undergraduate/computer-information-science/computer-science/bscs/
A10: CS 4400 | B10: Programming Languages | C10: Computer Science | D10: Concentration | E10: 4 | F10: Yes | G10: Software concentration | H10: https://catalog.northeastern.edu/undergraduate/computer-information-science/computer-science/bscs/
A11: CS 2800 | B11: Logic and Computation | C11: Computer Science | D11: Concentration | E11: 4 | F11: Yes | H11: https://catalog.northeastern.edu/undergraduate/computer-information-science/computer-science/bscs/
A12: DS 3000 | B12: Mathematical Foundations of Artificial Intelligence | C12: Computer Science | D12: Required | E12: 4 | F12: Yes | H12: https://catalog.northeastern.edu/undergraduate/computer-information-science/computer-science/bscs/
A13: ECON 1116 | B13: Principles of Microeconomics | C13: Economics | D13: Required | E13: 4 | F13: Yes | H13: https://catalog.northeastern.edu/undergraduate/social-sciences-humanities/economics/economics-mathematics-bs/
A14: ECON 1115 | B14: Principles of Macroeconomics | C14: Economics | D14: Required | E14: 4 | F14: Yes | H14: https://catalog.northeastern.edu/undergraduate/social-sciences-humanities/economics/economics-mathematics-bs/
A15: ECON 2316 | B15: Microeconomic Theory | C15: Economics | D15: Required | E15: 4 | F15: Yes | H15: https://catalog.northeastern.edu/undergraduate/social-sciences-humanities/economics/economics-mathematics-bs/
A16: ECON 2315 | B16: Macroeconomic Theory | C16: Economics | D16: Required | E16: 4 | F16: Yes | H16: https://catalog.northeastern.edu/undergraduate/social-sciences-humanities/economics/economics-mathematics-bs/
A17: ECON 2350 | B17: Statistics for Economists | C17: Economics | D17: Required (most majors) | E17: 4 | F17: Yes | H17: https://catalog.northeastern.edu/undergraduate/social-sciences-humanities/economics/economics-mathematics-bs/
A18: ECON 2560 | B18: Applied Econometrics | C18: Economics | D18: Required | E18: 4 | F18: Yes | H18: https://catalog.northeastern.edu/undergraduate/social-sciences-humanities/economics/economics-mathematics-bs/
A19: PSYC 1101 | B19: Foundations of Psychology | C19: Psychology | D19: Required | E19: 4 | F19: Yes | H19: https://catalog.northeastern.edu/undergraduate/science/psychology/psychology-bs
A20: PSYC 2320 | B20: Statistics in Psychological Research | C20: Psychology | D20: Required | E20: 4 | F20: Yes | H20: https://catalog.northeastern.edu/undergraduate/science/psychology/psychology-bs
A21: PSYC 3458 | B21: Biological Psychology | C21: Psychology | D21: Required (choose) | E21: 4 | F21: Yes | H21: https://catalog.northeastern.edu/undergraduate/science/psychology/psychology-bs
A22: PSYC 3402 | B22: Social Psychology | C22: Psychology | D22: Required (choose) | E22: 4 | F22: Yes | H22: https://catalog.northeastern.edu/undergraduate/science/psychology/psychology-bs
... A24: PSYC 3464 | B24: Psychology of Language | C24: Psychology | D24: Required (choose) | E24: 4 | F24: Yes | H24: https://catalog.northeastern.edu/undergraduate/science/psychology/psychology-bs
A25: BIOL 1107 | B25: Foundations of Biology | C25: Biology | D25: Core | E25: 5 | F25: Yes | G25: Includes BIOL 1108 lab | H25: https://catalog.northeastern.edu/undergraduate/science/biology/biology-bs/
A26: BIOL 1113 | B26: General Biology 2 | C26: Biology | D26: Core (some majors) | E26: 4 | F26: Yes | G26: Continues BIOL 1111 | H26: https://catalog.northeastern.edu/course-descriptions/biol
A27: BIOL 2299 | B27: Inquiries in Biological Sciences | C27: Biology | D27: Core | E27: 4 | F27: Yes | H27: https://catalog.northeastern.edu/undergraduate/science/biology/biology-bs/
A28: BIOL 2301 | B28: Genetics and Molecular Biology | C28: Biology | D28: Core | E28: 5 | F28: Yes | G28: Includes BIOL 2302 lab | H28: https://catalog.northeastern.edu/undergraduate/science/biology/biology-bs/
A29: BIOL 3611 | B29: Biochemistry | C29: Biology | D29: Core | E29: 5 | F29: Yes | G29: Includes BIOL 3612 lab | H29: https://catalog.northeastern.edu/undergraduate/science/biology/biology-bs/
A30: CHEM 1161 | B30: General Chemistry for Science Majors | C30: Biology | D30: Supporting (Chemistry) | E30: 5 | F30: Yes | G30: One-semester course with lab and recitation | H30: https://catalog.northeastern.edu/undergraduate/science/biology/biology-bs/
A31: CHEM 2311 | B31: Organic Chemistry 1 | C31: Biology | D31: Supporting (Chemistry) | E31: 5 | F31: Yes | G31: Includes CHEM 2312 lab | H31: https://catalog.northeastern.edu/undergraduate/science/biology/biology-bs/
A32: CHEM 2313 | B32: Organic Chemistry 2 | C32: Biology | D32: Supporting (Chemistry) | E32: 5 | F32: Yes | G32: Includes CHEM 2314 lab | H32: https://catalog.northeastern.edu/undergraduate/science/biology/biology-bs/
A33: MATH 1341 | B33: Calculus 1 for Science and Engineering | C33: Mathematics | D33: Supporting | E33: 4 | F33: Yes | H33: https://catalog.northeastern.edu/undergraduate/computer-information-science/computer-science/bscs/
A34: MATH 1342 | B34: Calculus 2 for Science and Engineering | C34: Mathematics | D34: Supporting | E34: 4 | F34: Yes | H34: https://catalog.northeastern.edu/undergraduate/science/biology/biology-mathematics-bs
A35: MATH 2321 | B35: Calculus 3 for Science and Engineering | C35: Mathematics | D35: Core | E35: 4 | F35: Check | G35: Code verified; title from memory | H35: https://catalog.northeastern.edu/undergraduate/science/biology/biology-mathematics-bs
A36: MATH 2331 | B36: Linear Algebra | C36: Mathematics | D36: Core | E36: 4 | F36: Check | G36: Code and title from memory; confirm in catalog | H36: https://catalog.northeastern.edu/undergraduate/science/biology/biology-mathematics-bs
A37: MATH 2341 | B37: Differential Equations and Linear Algebra for Engineering | C37: Mathematics | D37: Core | E37: 4 | F37: Check | G37: Code verified; title from memory | H37: https://catalog.northeastern.edu/undergraduate/science/biology/biology-mathematics-bs
A38: MATH 1365 | B38: Introduction to Mathematical Reasoning | C38: Mathematics | D38: Core | E38: 4 | F38: Yes | H38: https://catalog.northeastern.edu/undergraduate/computer-information-science/computer-science/bscs/
A39: MATH 3081 | B39: Probability and Statistics | C39: Mathematics | D39: Core | E39: 4 | F39: Yes | H39: https://catalog.northeastern.edu/undergraduate/science/biology/biology-mathematics-bs

Sheet NYU Courses
A1: Course code | B1: Course title | C1: Program | D1: Requirement type | E1: Credits | F1: Verified | G1: Notes | H1: Source
A2: CSCI-UA 101 | B2: Intro to Computer Science | C2: Computer Science | D2: Core | E2: 4 | F2: Yes | H2: https://bulletins.nyu.edu/undergraduate/arts-science/programs/computer-science-ba/computer-science-ba.pdf
A3: CSCI-UA 102 | B3: Data Structures | C3: Computer Science | D3: Core | E3: 4 | F3: Yes | H3: https://bulletins.nyu.edu/undergraduate/arts-science/programs/computer-science-ba/computer-science-ba.pdf
A4: CSCI-UA 201 | B4: Computer Systems Organization | C4: Computer Science | D4: Core | E4: 4 | F4: Yes | H4: https://bulletins.nyu.edu/undergraduate/arts-science/programs/computer-science-ba/computer-science-ba.pdf
A5: CSCI-UA 202 | B5: Operating Systems | C5: Computer Science | D5: Core | E5: 4 | F5: Yes | H5: https://bulletins.nyu.edu/undergraduate/arts-science/programs/computer-science-ba/computer-science-ba.pdf
A6: CSCI-UA 310 | B6: Basic Algorithms | C6: Computer Science | D6: Core | E6: 4 | F6: Yes | H6: https://bulletins.nyu.edu/undergraduate/arts-science/programs/computer-science-ba/computer-science-ba.pdf
A7: CSCI-UA 453 | B7: Theory of Computation | C7: Computer Science | D7: Joint/honors major | E7: 4 | F7: Yes | H7: https://math.nyu.edu/media/math/filer_public/f8/eb/f8eb4d2e-81c8-4421-8f62-fc2683e63e64/csma_major_honors_check_sheet.pdf
A8: MATH-UA 120 | B8: Discrete Mathematics | C8: Computer Science | D8: Core | E8: 4 | F8: Yes | H8: https://bulletins.nyu.edu/undergraduate/arts-science/programs/computer-science-ba/computer-science-ba.pdf
A9: ECON-UA 2 | B9: Introduction to Microeconomics | C9: Economics | D9: Intro | E9: 4 | F9: Yes | H9: https://bulletins.nyu.edu/undergraduate/arts-science/programs/economics-ba/economics-ba.pdf
A10: ECON-UA 1 | B10: Introduction to Macroeconomics | C10: Economics | D10: Intro | E10: 4 | F10: Yes | H10: https://bulletins.nyu.edu/undergraduate/arts-science/programs/economics-ba/economics-ba.pdf
A11: ECON-UA 10 | B11: Intermediate Microeconomics | C11: Economics | D11: Core (Policy) | E11: 4 | F11: Yes | G11: Theory track: ECON-UA 11 | H11: https://bulletins.nyu.edu/undergraduate/arts-science/programs/economics-ba/economics-ba.pdf
A12: ECON-UA 12 | B12: Intermediate Macroeconomics | C12: Economics | D12: Core (Policy) | E12: 4 | F12: Yes | G12: Theory track: ECON-UA 13 | H12: https://bulletins.nyu.edu/undergraduate/arts-science/programs/economics-ba/economics-ba.pdf
A13: ECON-UA 18 | B13: Statistics | C13: Economics | D13: Core (Policy) | E13: 4 | F13: Yes | G13: Theory track: ECON-UA 20 | H13: https://bulletins.nyu.edu/undergraduate/arts-science/programs/economics-ba/economics-ba.pdf
A14: ECON-UA 266 | B14: Intro to Econometrics | C14: Economics | D14: Core | E14: 4 | F14: Yes | H14: https://bulletins.nyu.edu/undergraduate/arts-science/programs/economics-ba/economics-ba.pdf
A15: PSYCH-UA 1 | B15: Intro to Psychology | C15: Psychology | D15: Intro | E15: 4 | F15: Yes | H15: https://bulletins.nyu.edu/courses/psych_ua/psych_ua.pdf
A16: PSYCH-UA 10 | B16: Statistics for the Behavioral Sciences | C16: Psychology | D16: Statistics | E16: 4 | F16: Yes | H16: https://bulletins.nyu.edu/courses/psych_ua/psych_ua.pdf
A17: PSYCH-UA 11 | B17: Statistics and Data Analysis for Research in Psychology | C17: Psychology | D17: Statistics | E17: 4 | F17: Yes | H17: https://bulletins.nyu.edu/courses/psych_ua/psych_ua.pdf
A18: PSYCH-UA 22 | B18: Perception | C18: Psychology | D18: Core (choose) | E18: 4 | F18: Yes | H18: https://bulletins.nyu.edu/courses/psych_ua/psych_ua.pdf
A19: PSYCH-UA 25 | B19: Cognitive Neuroscience | C19: Psychology | D19: Core (choose) | E19: 4 | F19: Yes | H19: https://bulletins.nyu.edu/courses/psych_ua/psych_ua.pdf
A20: PSYCH-UA 29 | B20: Cognition | C20: Psychology | D20: Core (choose) | E20: 4 | F20: Yes | H20: https://bulletins.nyu.edu/courses/psych_ua/psych_ua.pdf
A21: PSYCH-UA 30 | B21: Personality | C21: Psychology | D21: Core (choose) | E21: 4 | F21: Yes | H21: https://bulletins.nyu.edu/courses/psych_ua/psych_ua.pdf
A22: PSYCH-UA 32 | B22: Social Psychology | C22: Psychology | D22: Core (choose) | E22: 4 | F22: Yes | H22: https://bulletins.nyu.edu/courses/psych_ua/psych_ua.pdf
A23: PSYCH-UA 34 | B23: Developmental Psychology | C23: Psychology | D23: Core (choose) | E23: 4 | F23: Yes | H23: https://bulletins.nyu.edu/courses/psych_ua/psych_ua.pdf
A24: PSYCH-UA 51 | B24: Abnormal Psychology | C24: Psychology | D24: Elective | E24: 4 | F24: Yes | H24: https://bulletins.nyu.edu/courses/psych_ua/psych_ua.pdf
A25: BIOL-UA 11 | B25: Principles of Biology I | C25: Biology | D25: Required | E25: 4 | F25: Yes | H25: https://courses.bio.nyu.edu/requirement/major-standard-track/required
... A28: BIOL-UA 30 | B28: Genetics | C28: Biology | D28: Elective / minor | E28: 4 | F28: Yes | H28: https://courses.bio.nyu.edu/requirement/minor-genetics
A29: CHEM-UA 125 | B29: General Chemistry I | C29: Biology | D29: Supporting (Chemistry) | E29: 5 | F29: Check | G29: Code verified; title and credits from memory | H29: https://www.tmdsas.com/course-listings/Schools/NYU_SU11-SU12.html
A30: CHEM-UA 126 | B30: General Chemistry II | C30: Biology | D30: Supporting (Chemistry) | E30: 5 | F30: Check | G30: Code verified; title and credits from memory | H30: https://www.tmdsas.com/course-listings/Schools/NYU_SU11-SU12.html
A31: CHEM-UA 225 | B31: Organic Chemistry I | C31: Biology | D31: Supporting (Chemistry) | E31: 5 | F31: Check | G31: Code verified; title and credits from memory | H31: https://www.tmdsas.com/course-listings/Schools/NYU_SU11-SU12.html
A32: CHEM-UA 226 | B32: Organic Chemistry II | C32: Biology | D32: Supporting (Chemistry) | E32: 5 | F32: Check | G32: Code verified; title and credits from memory | H32: https://www.tmdsas.com/course-listings/Schools/NYU_SU11-SU12.html
A33: MATH-UA 121 | B33: Calculus I | C33: Mathematics | D33: Core | E33: 4 | F33: Yes | H33: https://math.nyu.edu/media/math/filer_public/f8/eb/f8eb4d2e-81c8-4421-8f62-fc2683e63e64/csma_major_honors_check_sheet.pdf
A34: MATH-UA 122 | B34: Calculus II | C34: Mathematics | D34: Core | E34: 4 | F34: Yes | H34: https://math.nyu.edu/media/math/filer_public/f8/eb/f8eb4d2e-81c8-4421-8f62-fc2683e63e64/csma_major_honors_check_sheet.pdf
A35: MATH-UA 123 | B35: Calculus III | C35: Mathematics | D35: Core | E35: 4 | F35: Yes | H35: https://math.nyu.edu/media/math/filer_public/f8/eb/f8eb4d2e-81c8-4421-8f62-fc2683e63e64/csma_major_honors_check_sheet.pdf
A36: MATH-UA 140 | B36: Linear Algebra | C36: Mathematics | D36: Core | E36: 4 | F36: Yes | H36: https://math.nyu.edu/media/math/filer_public/f8/eb/f8eb4d2e-81c8-4421-8f62-fc2683e63e64/csma_major_honors_check_sheet.pdf
A37: MATH-UA 262 | B37: Ordinary Differential Equations | C37: Mathematics | D37: Elective | E37: 4 | F37: Yes | H37: https://math.nyu.edu/media/math/filer_public/32/54/32545937-adf4-4d3e-9592-b41a155c83fc/ecma_major_check_sheet_as_of_2014.pdf
A38: MATH-UA 233 | B38: Theory of Probability | C38: Mathematics | D38: Elective | E38: 4 | F38: Yes | H38: https://math.nyu.edu/media/math/filer_public/32/54/32545937-adf4-4d3e-9592-b41a155c83fc/ecma_major_check_sheet_as_of_2014.pdf
A39: MATH-UA 235 | B39: Probability & Statistics | C39: Mathematics | D39: Elective | E39: 4 | F39: Yes | H39: https://math.nyu.edu/media/math/filer_public/32/54/32545937-adf4-4d3e-9592-b41a155c83fc/ecma_major_check_sheet_as_of_2014.pdf

Sheet Course Match
A1: BU course | B1: BU title | C1: Program | D1: BU credits | E1: Northeastern course | F1: NU title | G1: NU credits | H1: NU match level | I1: NYU course | J1: NYU title | K1: NYU credits | L1: NYU match level | M1: Notes
A2: CAS CS 111 | B2: =IF(A2="—","—",IFERROR(INDEX('BU Courses'!$B$2:$B$42,MATCH(A2,'BU Courses'!$A$2:$A$42,0)),"Not in sheet")) -> Introduction to Computer Science 1 | C2: =IF(A2="—","—",IFERROR(INDEX('BU Courses'!$C$2:$C$42,MATCH(A2,'BU Courses'!$A$2:$A$42,0)),"Not in sheet")) -> Computer Science | D2: =IF(A2="—","—",IFERROR(INDEX('BU Courses'!$E$2:$E$42,MATCH(A2,'BU Courses'!$A$2:$A$42,0)),"Not in sheet")) -> 4 | E2: CS 2000 | F2: =IF(E2="—","—",IFERROR(INDEX('Northeastern Courses'!$B$2:$B$39,MATCH(E2,'Northeastern Courses'!$A$2:$A$39,0)),"Not in sheet")) -> Introduction to Program Design and Implementation | G2: =IF(E2="—","—",IFERROR(INDEX('Northeastern Courses'!$E$2:$E$39,MATCH(E2,'Northeastern Courses'!$A$2:$A$39,0)),"Not in sheet")) -> 5 | H2: Likely equivalent | I2: CSCI-UA 101 | J2: =IF(I2="—","—",IFERROR(INDEX('NYU Courses'!$B$2:$B$39,MATCH(I2,'NYU Courses'!$A$2:$A$39,0)),"Not in sheet")) -> Intro to Computer Science | K2: =IF(I2="—","—",IFERROR(INDEX('NYU Courses'!$E$2:$E$39,MATCH(I2,'NYU Courses'!$A$2:$A$39,0)),"Not in sheet")) -> 4 | L2: Likely equivalent | M2: Intro programming courses.
A3: CAS CS 112 | B3: =IF(A3="—","—",IFERROR(INDEX('BU Courses'!$B$2:$B$42,MATCH(A3,'BU Courses'!$A$2:$A$42,0)),"Not in sheet")) -> Introduction to Computer Science 2 | C3: =IF(A3="—","—",IFERROR(INDEX('BU Courses'!$C$2:$C$42,MATCH(A3,'BU Courses'!$A$2:$A$42,0)),"Not in sheet")) -> Computer Science | D3: =IF(A3="—","—",IFERROR(INDEX('BU Courses'!$E$2:$E$42,MATCH(A3,'BU Courses'!$A$2:$A$42,0)),"Not in sheet")) -> 4 | E3: CS 2100 | F3: =IF(E3="—","—",IFERROR(INDEX('Northeastern Courses'!$B$2:$B$39,MATCH(E3,'Northeastern Courses'!$A$2:$A$39,0)),"Not in sheet")) -> Program Design and Implementation 1 | G3: =IF(E3="—","—",IFERROR(INDEX('Northeastern Courses'!$E$2:$E$39,MATCH(E3,'Northeastern Courses'!$A$2:$A$39,0)),"Not in sheet")) -> 5 | H3: Partial - syllabus review | I3: CSCI-UA 102 | J3: =IF(I3="—","—",IFERROR(INDEX('NYU Courses'!$B$2:$B$39,MATCH(I3,'NYU Courses'!$A$2:$A$39,0)),"Not in sheet")) -> Data Structures | K3: =IF(I3="—","—",IFERROR(INDEX('NYU Courses'!$E$2:$E$39,MATCH(I3,'NYU Courses'!$A$2:$A$39,0)),"Not in sheet")) -> 4 | L3: Likely equivalent | M3: NU splits program design (CS 2100) and data structures (CS 2700); evaluator may need both.
A4: CAS CS 131 | B4: =IF(A4="—","—",IFERROR(INDEX('BU Courses'!$B$2:$B$42,MATCH(A4,'BU Courses'!$A$2:$A$42,0)),"Not in sheet")) -> Combinatoric Structures | C4: =IF(A4="—","—",IFERROR(INDEX('BU Courses'!$C$2:$C$42,MATCH(A4,'BU Courses'!$A$2:$A$42,0)),"Not in sheet")) -> Computer Science | D4: =IF(A4="—","—",IFERROR(INDEX('BU Courses'!$E$2:$E$42,MATCH(A4,'BU Courses'!$A$2:$A$42,0)),"Not in sheet")) -> 4 | E4: CS 1800 | F4: =IF(E4="—","—",IFERROR(INDEX('Northeastern Courses'!$B$2:$B$39,MATCH(E4,'Northeastern Courses'!$A$2:$A$39,0)),"Not in sheet")) -> Discrete Structures | G4: =IF(E4="—","—",IFERROR(INDEX('Northeastern Courses'!$E$2:$E$39,MATCH(E4,'Northeastern Courses'!$A$2:$A$39,0)),"Not in sheet")) -> 4 | H4: Likely equivalent | I4: MATH-UA 120 | J4: =IF(I4="—","—",IFERROR(INDEX('NYU Courses'!$B$2:$B$39,MATCH(I4,'NYU Courses'!$A$2:$A$39,0)),"Not in sheet")) -> Discrete Mathematics | K4: =IF(I4="—","—",IFERROR(INDEX('NYU Courses'!$E$2:$E$39,MATCH(I4,'NYU Courses'!$A$2:$A$39,0)),"Not in sheet")) -> 4 | L4: Likely equivalent | M4: Discrete structures / discrete math.
A5: CAS CS 210 | B5: =IF(A5="—","—",IFERROR(INDEX('BU Courses'!$B$2:$B$42,MATCH(A5,'BU Courses'!$A$2:$A$42,0)),"Not in sheet")) -> Computer Systems | C5: =IF(A5="—","—",IFERROR(INDEX('BU Courses'!$C$2:$C$42,MATCH(A5,'BU Courses'!$A$2:$A$42,0)),"Not in sheet")) -> Computer Science | D5: =IF(A5="—","—",IFERROR(INDEX('BU Courses'!$E$2:$E$42,MATCH(A5,'BU Courses'!$A$2:$A$42,0)),"Not in sheet")) -> 4 | E5: CS 3650 | F5: =IF(E5="—","—",IFERROR(INDEX('Northeastern Courses'!$B$2:$B$39,MATCH(E5,'Northeastern Courses'!$A$2:$A$39,0)),"Not in sheet")) -> Computer Systems | G5: =IF(E5="—","—",IFERROR(INDEX('Northeastern Courses'!$E$2:$E$39,MATCH(E5,'Northeastern Courses'!$A$2:$A$39,0)),"Not in sheet")) -> 4 | H5: Likely equivalent | I5: CSCI-UA 201 | J5: =IF(I5="—","—",IFERROR(INDEX('NYU Courses'!$B$2:$B$39,MATCH(I5,'NYU Courses'!$A$2:$A$39,0)),"Not in sheet")) -> Computer Systems Organization | K5: =IF(I5="—","—",IFERROR(INDEX('NYU Courses'!$E$2:$E$39,MATCH(I5,'NYU Courses'!$A$2:$A$39,0)),"Not in sheet")) -> 4 | L5: Likely equivalent | M5: Computer systems / organization.
A6: CAS CS 330 | B6: =IF(A6="—","—",IFERROR(INDEX('BU Courses'!$B$2:$B$42,MATCH(A6,'BU Courses'!$A$2:$A$42,0)),"Not in sheet")) -> Introduction to the Analysis of Algorithms | C6: =IF(A6="—","—",IFERROR(INDEX('BU Courses'!$C$2:$C$42,MATCH(A6,'BU Courses'!$A$2:$A$42,0)),"Not in sheet")) -> Computer Science | D6: =IF(A6="—","—",IFERROR(INDEX('BU Courses'!$E$2:$E$42,MATCH(A6,'BU Courses'!$A$2:$A$42,0)),"Not in sheet")) -> 4 | E6: CS 3000 | F6: =IF(E6="—","—",IFERROR(INDEX('Northeastern Courses'!$B$2:$B$39,MATCH(E6,'Northeastern Courses'!$A$2:$A$39,0)),"Not in sheet")) -> Algorithms and Data | G6: =IF(E6="—","—",IFERROR(INDEX('Northeastern Courses'!$E$2:$E$39,MATCH(E6,'Northeastern Courses'!$A$2:$A$39,0)),"Not in sheet")) -> 4 | H6: Likely equivalent | I6: CSCI-UA 310 | J6: =IF(I6="—","—",IFERROR(INDEX('NYU Courses'!$B$2:$B$39,MATCH(I6,'NYU Courses'!$A$2:$A$39,0)),"Not in sheet")) -> Basic Algorithms | K6: =IF(I6="—","—",IFERROR(INDEX('NYU Courses'!$E$2:$E$39,MATCH(I6,'NYU Courses'!$A$2:$A$39,0)),"Not in sheet")) -> 4 | L6: Likely equivalent | M6: Algorithms.
A7: CAS CS 132 | B7: =IF(A7="—","—",IFERROR(INDEX('BU Courses'!$B$2:$B$42,MATCH(A7,'BU Courses'!$A$2:$A$42,0)),"Not in sheet")) -> Geometric Algorithms | C7: =IF(A7="—","—",IFERROR(INDEX('BU Courses'!$C$2:$C$42,MATCH(A7,'BU Courses'!$A$2:$A$42,0)),"Not in sheet")) -> Computer Science | D7: =IF(A7="—","—",IFERROR(INDEX('BU Courses'!$E$2:$E$42,MATCH(A7,'BU Courses'!$A$2:$A$42,0)),"Not in sheet")) -> 4 | E7: MATH 2331 | F7: =IF(E7="—","—",IFERROR(INDEX('Northeastern Courses'!$B$2:$B$39,MATCH(E7,'Northeastern Courses'!$A$2:$A$39,0)),"Not in sheet")) -> Linear Algebra | G7: =IF(E7="—","—",IFERROR(INDEX('Northeastern Courses'!$E$2:$E$39,MATCH(E7,'Northeastern Courses'!$A$2:$A$39,0)),"Not in sheet")) -> 4 | H7: Partial - syllabus review | I7: MATH-UA 140 | J7: =IF(I7="—","—",IFERROR(INDEX('NYU Courses'!$B$2:$B$39,MATCH(I7,'NYU Courses'!$A$2:$A$39,0)),"Not in sheet")) -> Linear Algebra | K7: =IF(I7="—","—",IFERROR(INDEX('NYU Courses'!$E$2:$E$39,MATCH(I7,'NYU Courses'!$A$2:$A$39,0)),"Not in sheet")) -> 4 | L7: Partial - syllabus review | M7: BU allows MA 242 (Linear Algebra) to substitute for CS 132.
A8: CAS CS 235 | B8: =IF(A8="—","—",IFERROR(INDEX('BU Courses'!$B$2:$B$42,MATCH(A8,'BU Courses'!$A$2:$A$42,0)),"Not in sheet")) -> Algebraic Algorithms | C8: =IF(A8="—","—",IFERROR(INDEX('BU Courses'!$C$2:$C$42,MATCH(A8,'BU Courses'!$A$2:$A$42,0)),"Not in sheet")) -> Computer Science | D8: =IF(A8="—","—",IFERROR(INDEX('BU Courses'!$E$2:$E$42,MATCH(A8,'BU Courses'!$A$2:$A$42,0)),"Not in sheet")) -> 4 | E8: — | F8: =IF(E8="—","—",IFERROR(INDEX('Northeastern Courses'!$B$2:$B$39,MATCH(E8,'Northeastern Courses'!$A$2:$A$39,0)),"Not in sheet")) -> — | G8: =IF(E8="—","—",IFERROR(INDEX('Northeastern Courses'!$E$2:$E$39,MATCH(E8,'Northeastern Courses'!$A$2:$A$39,0)),"Not in sheet")) -> — | H8: No equivalent found | I8: — | J8: =IF(I8="—","—",IFERROR(INDEX('NYU Courses'!$B$2:$B$39,MATCH(I8,'NYU Courses'!$A$2:$A$39,0)),"Not in sheet")) -> — | K8: =IF(I8="—","—",IFERROR(INDEX('NYU Courses'!$E$2:$E$39,MATCH(I8,'NYU Courses'!$A$2:$A$39,0)),"Not in sheet")) -> — | L8: No equivalent found | M8: No algebraic-algorithms course in the core of either peer.
A9: CAS CS 237 | B9: =IF(A9="—","—",IFERROR(INDEX('BU Courses'!$B$2:$B$42,MATCH(A9,'BU Courses'!$A$2:$A$42,0)),"Not in sheet")) -> Probability in Computing | C9: =IF(A9="—","—",IFERROR(INDEX('BU Courses'!$C$2:$C$42,MATCH(A9,'BU Courses'!$A$2:$A$42,0)),"Not in sheet")) -> Computer Science | D9: =IF(A9="—","—",IFERROR(INDEX('BU Courses'!$E$2:$E$42,MATCH(A9,'BU Courses'!$A$2:$A$42,0)),"Not in sheet")) -> 4 | E9: MATH 3081 | F9: =IF(E9="—","—",IFERROR(INDEX('Northeastern Courses'!$B$2:$B$39,MATCH(E9,'Northeastern Courses'!$A$2:$A$39,0)),"Not in sheet")) -> Probability and Statistics | G9: =IF(E9="—","—",IFERROR(INDEX('Northeastern Courses'!$E$2:$E$39,MATCH(E9,'Northeastern Courses'!$A$2:$A$39,0)),"Not in sheet")) -> 4 | H9: Partial - syllabus review | I9: MATH-UA 233 | J9: =IF(I9="—","—",IFERROR(INDEX('NYU Courses'!$B$2:$B$39,MATCH(I9,'NYU Courses'!$A$2:$A$39,0)),"Not in sheet")) -> Theory of Probability | K9: =IF(I9="—","—",IFERROR(INDEX('NYU Courses'!$E$2:$E$39,MATCH(I9,'NYU Courses'!$A$2:$A$39,0)),"Not in sheet")) -> 4 | L9: Partial - syllabus review | M9: BU allows MA 581 (Probability) to substitute for CS 237.
A10: CAS CS 320 | B10: =IF(A10="—","—",IFERROR(INDEX('BU Courses'!$B$2:$B$42,MATCH(A10,'BU Courses'!$A$2:$A$42,0)),"Not in sheet")) -> Concepts of Programming Languages | C10: =IF(A10="—","—",IFERROR(INDEX('BU Courses'!$C$2:$C$42,MATCH(A10,'BU Courses'!$A$2:$A$42,0)),"Not in sheet")) -> Computer Science | D10: =IF(A10="—","—",IFERROR(INDEX('BU Courses'!$E$2:$E$42,MATCH(A10,'BU Courses'!$A$2:$A$42,0)),"Not in sheet")) -> 4 | E10: CS 4400 | F10: =IF(E10="—","—",IFERROR(INDEX('Northeastern Courses'!$B$2:$B$39,MATCH(E10,'Northeastern Courses'!$A$2:$A$39,0)),"Not in sheet")) -> Programming Languages | G10: =IF(E10="—","—",IFERROR(INDEX('Northeastern Courses'!$E$2:$E$39,MATCH(E10,'Northeastern Courses'!$A$2:$A$39,0)),"Not in sheet")) -> 4 | H10: Must be taken at BU | I10: — | J10: =IF(I10="—","—",IFERROR(INDEX('NYU Courses'!$B$2:$B$39,MATCH(I10,'NYU Courses'!$A$2:$A$39,0)),"Not in sheet")) -> — | K10: =IF(I10="—","—",IFERROR(INDEX('NYU Courses'!$E$2:$E$39,MATCH(I10,'NYU Courses'!$A$2:$A$39,0)),"Not in sheet")) -> — | L10: Must be taken at BU | M10: Group C: BU only, even if a similar course exists.
A11: CAS CS 332 | B11: =IF(A11="—","—",IFERROR(INDEX('BU Courses'!$B$2:$B$42,MATCH(A11,'BU Courses'!$A$2:$A$42,0)),"Not in sheet")) -> Elements of the Theory of Computation | C11: =IF(A11="—","—",IFERROR(INDEX('BU Courses'!$C$2:$C$42,MATCH(A11,'BU Courses'!$A$2:$A$42,0)),"Not in sheet")) -> Computer Science | D11: =IF(A11="—","—",IFERROR(INDEX('BU Courses'!$E$2:$E$42,MATCH(A11,'BU Courses'!$A$2:$A$42,0)),"Not in sheet")) -> 4 | E11: CS 3800 | F11: =IF(E11="—","—",IFERROR(INDEX('Northeastern Courses'!$B$2:$B$39,MATCH(E11,'Northeastern Courses'!$A$2:$A$39,0)),"Not in sheet")) -> Theory of Computation | G11: =IF(E11="—","—",IFERROR(INDEX('Northeastern Courses'!$E$2:$E$39,MATCH(E11,'Northeastern Courses'!$A$2:$A$39,0)),"Not in sheet")) -> 4 | H11: Must be taken at BU | I11: CSCI-UA 453 | J11: =IF(I11="—","—",IFERROR(INDEX('NYU Courses'!$B$2:$B$39,MATCH(I11,'NYU Courses'!$A$2:$A$39,0)),"Not in sheet")) -> Theory of Computation | K11: =IF(I11="—","—",IFERROR(INDEX('NYU Courses'!$E$2:$E$39,MATCH(I11,'NYU Courses'!$A$2:$A$39,0)),"Not in sheet")) -> 4 | L11: Must be taken at BU | M11: Group C: BU only, even if a similar course exists.
A12: CAS CS 350 | B12: =IF(A12="—","—",IFERROR(INDEX('BU Courses'!$B$2:$B$42,MATCH(A12,'BU Courses'!$A$2:$A$42,0)),"Not in sheet")) -> Fundamentals of Computing Systems | C12: =IF(A12="—","—",IFERROR(INDEX('BU Courses'!$C$2:$C$42,MATCH(A12,'BU Courses'!$A$2:$A$42,0)),"Not in sheet")) -> Computer Science | D12: =IF(A12="—","—",IFERROR(INDEX('BU Courses'!$E$2:$E$42,MATCH(A12,'BU Courses'!$A$2:$A$42,0)),"Not in sheet")) -> 4 | E12: — | F12: =IF(E12="—","—",IFERROR(INDEX('Northeastern Courses'!$B$2:$B$39,MATCH(E12,'Northeastern Courses'!$A$2:$A$39,0)),"Not in sheet")) -> — | G12: =IF(E12="—","—",IFERROR(INDEX('Northeastern Courses'!$E$2:$E$39,MATCH(E12,'Northeastern Courses'!$A$2:$A$39,0)),"Not in sheet")) -> — | H12: Must be taken at BU | I12: CSCI-UA 202 | J12: =IF(I12="—","—",IFERROR(INDEX('NYU Courses'!$B$2:$B$39,MATCH(I12,'NYU Courses'!$A$2:$A$39,0)),"Not in sheet")) -> Operating Systems | K12: =IF(I12="—","—",IFERROR(INDEX('NYU Courses'!$E$2:$E$39,MATCH(I12,'NYU Courses'!$A$2:$A$39,0)),"Not in sheet")) -> 4 | L12: Must be taken at BU | M12: Group C: BU only, even if a similar course exists.
A13: CAS EC 101 | B13: =IF(A13="—","—",IFERROR(INDEX('BU Courses'!$B$2:$B$42,MATCH(A13,'BU Courses'!$A$2:$A$42,0)),"Not in sheet")) -> Introductory Microeconomic Analysis | C13: =IF(A13="—","—",IFERROR(INDEX('BU Courses'!$C$2:$C$42,MATCH(A13,'BU Courses'!$A$2:$A$42,0)),"Not in sheet")) -> Economics | D13: =IF(A13="—","—",IFERROR(INDEX('BU Courses'!$E$2:$E$42,MATCH(A13,'BU Courses'!$A$2:$A$42,0)),"Not in sheet")) -> 4 | E13: ECON 1116 | F13: =IF(E13="—","—",IFERROR(INDEX('Northeastern Courses'!$B$2:$B$39,MATCH(E13,'Northeastern Courses'!$A$2:$A$39,0)),"Not in sheet")) -> Principles of Microeconomics | G13: =IF(E13="—","—",IFERROR(INDEX('Northeastern Courses'!$E$2:$E$39,MATCH(E13,'Northeastern Courses'!$A$2:$A$39,0)),"Not in sheet")) -> 4 | H13: Likely equivalent | I13: ECON-UA 2 | J13: =IF(I13="—","—",IFERROR(INDEX('NYU Courses'!$B$2:$B$39,MATCH(I13,'NYU Courses'!$A$2:$A$39,0)),"Not in sheet")) -> Introduction to Microeconomics | K13: =IF(I13="—","—",IFERROR(INDEX('NYU Courses'!$E$2:$E$39,MATCH(I13,'NYU Courses'!$A$2:$A$39,0)),"Not in sheet")) -> 4 | L13: Likely equivalent | M13: Principles of microeconomics.
... A42: CAS MA 581 | B42: =IF(A42="—","—",IFERROR(INDEX('BU Courses'!$B$2:$B$42,MATCH(A42,'BU Courses'!$A$2:$A$42,0)),"Not in sheet")) -> Probability | C42: =IF(A42="—","—",IFERROR(INDEX('BU Courses'!$C$2:$C$42,MATCH(A42,'BU Courses'!$A$2:$A$42,0)),"Not in sheet")) -> Mathematics | D42: =IF(A42="—","—",IFERROR(INDEX('BU Courses'!$E$2:$E$42,MATCH(A42,'BU Courses'!$A$2:$A$42,0)),"Not in sheet")) -> 4 | E42: MATH 3081 | F42: =IF(E42="—","—",IFERROR(INDEX('Northeastern Courses'!$B$2:$B$39,MATCH(E42,'Northeastern Courses'!$A$2:$A$39,0)),"Not in sheet")) -> Probability and Statistics | G42: =IF(E42="—","—",IFERROR(INDEX('Northeastern Courses'!$E$2:$E$39,MATCH(E42,'Northeastern Courses'!$A$2:$A$39,0)),"Not in sheet")) -> 4 | H42: Partial - syllabus review | I42: MATH-UA 233 | J42: =IF(I42="—","—",IFERROR(INDEX('NYU Courses'!$B$2:$B$39,MATCH(I42,'NYU Courses'!$A$2:$A$39,0)),"Not in sheet")) -> Theory of Probability | K42: =IF(I42="—","—",IFERROR(INDEX('NYU Courses'!$E$2:$E$39,MATCH(I42,'NYU Courses'!$A$2:$A$39,0)),"Not in sheet")) -> 4 | L42: Likely equivalent | M42: NU course combines probability and statistics.
A44: Blue course codes are inputs; titles and credits are pulled by formula from the course sheets. Match levels are preliminary and can be changed from the dropdown.

Sheet Match Summary
A1: Match Summary by Program
A2: All counts and percentages are formulas over the Course Match sheet.
A4: BU ↔ Northeastern
A5: Program | B5: BU courses | C5: Likely equivalent | D5: Partial - syllabus review | E5: No equivalent found | F5: Must be taken at BU | G5: % likely equivalent
A6: Computer Science | B6: =COUNTIF('Course Match'!$C$2:$C$42,$A6) -> 11 | C6: =COUNTIFS('Course Match'!$C$2:$C$42,$A6,'Course Match'!$H$2:$H$42,C$5) -> 4 | D6: =COUNTIFS('Course Match'!$C$2:$C$42,$A6,'Course Match'!$H$2:$H$42,D$5) -> 3 | E6: =COUNTIFS('Course Match'!$C$2:$C$42,$A6,'Course Match'!$H$2:$H$42,E$5) -> 1 | F6: =COUNTIFS('Course Match'!$C$2:$C$42,$A6,'Course Match'!$H$2:$H$42,F$5) -> 3 | G6: =IF(B6=0,0,C6/B6) -> 0.36363636
A7: Economics | B7: =COUNTIF('Course Match'!$C$2:$C$42,$A7) -> 6 | C7: =COUNTIFS('Course Match'!$C$2:$C$42,$A7,'Course Match'!$H$2:$H$42,C$5) -> 5 | D7: =COUNTIFS('Course Match'!$C$2:$C$42,$A7,'Course Match'!$H$2:$H$42,D$5) -> 1 | E7: =COUNTIFS('Course Match'!$C$2:$C$42,$A7,'Course Match'!$H$2:$H$42,E$5) -> 0 | F7: =COUNTIFS('Course Match'!$C$2:$C$42,$A7,'Course Match'!$H$2:$H$42,F$5) -> 0 | G7: =IF(B7=0,0,C7/B7) -> 0.83333333
A8: Psychology | B8: =COUNTIF('Course Match'!$C$2:$C$42,$A8) -> 9 | C8: =COUNTIFS('Course Match'!$C$2:$C$42,$A8,'Course Match'!$H$2:$H$42,C$5) -> 4 | D8: =COUNTIFS('Course Match'!$C$2:$C$42,$A8,'Course Match'!$H$2:$H$42,D$5) -> 1 | E8: =COUNTIFS('Course Match'!$C$2:$C$42,$A8,'Course Match'!$H$2:$H$42,E$5) -> 4 | F8: =COUNTIFS('Course Match'!$C$2:$C$42,$A8,'Course Match'!$H$2:$H$42,F$5) -> 0 | G8: =IF(B8=0,0,C8/B8) -> 0.44444444
A9: Biology | B9: =COUNTIF('Course Match'!$C$2:$C$42,$A9) -> 8 | C9: =COUNTIFS('Course Match'!$C$2:$C$42,$A9,'Course Match'!$H$2:$H$42,C$5) -> 4 | D9: =COUNTIFS('Course Match'!$C$2:$C$42,$A9,'Course Match'!$H$2:$H$42,D$5) -> 3 | E9: =COUNTIFS('Course Match'!$C$2:$C$42,$A9,'Course Match'!$H$2:$H$42,E$5) -> 1 | F9: =COUNTIFS('Course Match'!$C$2:$C$42,$A9,'Course Match'!$H$2:$H$42,F$5) -> 0 | G9: =IF(B9=0,0,C9/B9) -> 0.5
A10: Mathematics | B10: =COUNTIF('Course Match'!$C$2:$C$42,$A10) -> 7 | C10: =COUNTIFS('Course Match'!$C$2:$C$42,$A10,'Course Match'!$H$2:$H$42,C$5) -> 4 | D10: =COUNTIFS('Course Match'!$C$2:$C$42,$A10,'Course Match'!$H$2:$H$42,D$5) -> 3 | E10: =COUNTIFS('Course Match'!$C$2:$C$42,$A10,'Course Match'!$H$2:$H$42,E$5) -> 0 | F10: =COUNTIFS('Course Match'!$C$2:$C$42,$A10,'Course Match'!$H$2:$H$42,F$5) -> 0 | G10: =IF(B10=0,0,C10/B10) -> 0.57142857
A11: Total | B11: =SUM(B6:B10) -> 41 | C11: =SUM(C6:C10) -> 21 | D11: =SUM(D6:D10) -> 11 | E11: =SUM(E6:E10) -> 6 | F11: =SUM(F6:F10) -> 3 | G11: =IF(B11=0,0,C11/B11) -> 0.51219512
A14: BU ↔ NYU
A15: Program | B15: BU courses | C15: Likely equivalent | D15: Partial - syllabus review | E15: No equivalent found | F15: Must be taken at BU | G15: % likely equivalent
A16: Computer Science | B16: =COUNTIF('Course Match'!$C$2:$C$42,$A16) -> 11 | C16: =COUNTIFS('Course Match'!$C$2:$C$42,$A16,'Course Match'!$L$2:$L$42,C$15) -> 5 | D16: =COUNTIFS('Course Match'!$C$2:$C$42,$A16,'Course Match'!$L$2:$L$42,D$15) -> 2 | E16: =COUNTIFS('Course Match'!$C$2:$C$42,$A16,'Course Match'!$L$2:$L$42,E$15) -> 1 | F16: =COUNTIFS('Course Match'!$C$2:$C$42,$A16,'Course Match'!$L$2:$L$42,F$15) -> 3 | G16: =IF(B16=0,0,C16/B16) -> 0.45454545
A17: Economics | B17: =COUNTIF('Course Match'!$C$2:$C$42,$A17) -> 6 | C17: =COUNTIFS('Course Match'!$C$2:$C$42,$A17,'Course Match'!$L$2:$L$42,C$15) -> 5 | D17: =COUNTIFS('Course Match'!$C$2:$C$42,$A17,'Course Match'!$L$2:$L$42,D$15) -> 1 | E17: =COUNTIFS('Course Match'!$C$2:$C$42,$A17,'Course Match'!$L$2:$L$42,E$15) -> 0 | F17: =COUNTIFS('Course Match'!$C$2:$C$42,$A17,'Course Match'!$L$2:$L$42,F$15) -> 0 | G17: =IF(B17=0,0,C17/B17) -> 0.83333333
A18: Psychology | B18: =COUNTIF('Course Match'!$C$2:$C$42,$A18) -> 9 | C18: =COUNTIFS('Course Match'!$C$2:$C$42,$A18,'Course Match'!$L$2:$L$42,C$15) -> 7 | D18: =COUNTIFS('Course Match'!$C$2:$C$42,$A18,'Course Match'!$L$2:$L$42,D$15) -> 2 | E18: =COUNTIFS('Course Match'!$C$2:$C$42,$A18,'Course Match'!$L$2:$L$42,E$15) -> 0 | F18: =COUNTIFS('Course Match'!$C$2:$C$42,$A18,'Course Match'!$L$2:$L$42,F$15) -> 0 | G18: =IF(B18=0,0,C18/B18) -> 0.77777778
A19: Biology | B19: =COUNTIF('Course Match'!$C$2:$C$42,$A19) -> 8 | C19: =COUNTIFS('Course Match'!$C$2:$C$42,$A19,'Course Match'!$L$2:$L$42,C$15) -> 7 | D19: =COUNTIFS('Course Match'!$C$2:$C$42,$A19,'Course Match'!$L$2:$L$42,D$15) -> 1 | E19: =COUNTIFS('Course Match'!$C$2:$C$42,$A19,'Course Match'!$L$2:$L$42,E$15) -> 0 | F19: =COUNTIFS('Course Match'!$C$2:$C$42,$A19,'Course Match'!$L$2:$L$42,F$15) -> 0 | G19: =IF(B19=0,0,C19/B19) -> 0.875
A20: Mathematics | B20: =COUNTIF('Course Match'!$C$2:$C$42,$A20) -> 7 | C20: =COUNTIFS('Course Match'!$C$2:$C$42,$A20,'Course Match'!$L$2:$L$42,C$15) -> 7 | D20: =COUNTIFS('Course Match'!$C$2:$C$42,$A20,'Course Match'!$L$2:$L$42,D$15) -> 0 | E20: =COUNTIFS('Course Match'!$C$2:$C$42,$A20,'Course Match'!$L$2:$L$42,E$15) -> 0 | F20: =COUNTIFS('Course Match'!$C$2:$C$42,$A20,'Course Match'!$L$2:$L$42,F$15) -> 0 | G20: =IF(B20=0,0,C20/B20) -> 1
A21: Total | B21: =SUM(B16:B20) -> 41 | C21: =SUM(C16:C20) -> 31 | D21: =SUM(D16:D20) -> 6 | E21: =SUM(E16:E20) -> 1 | F21: =SUM(F16:F20) -> 3 | G21: =IF(B21=0,0,C21/B21) -> 0.75609756
